Workbook

Sheet Tabelle 1
A1: V. dahliae - plant experiment with
A2: spore conc. 1x10^7 Sp/ml, infection 40 min root dipping while shaking (35 rpm)
A3: Infection on (infected 10 day-old seedlings)
A4: date of measurement:
A5: Stem assay: 8 min EtOH, 8 min NaClO, 2 x H2O
A7: MOCK A | B7: Height (soil - veg. point) | C7: Length of longest leaf in cm | D7: Weight in g | E7: Hypocotyl discoloration
A8: Replikat
A9: 1 | B9: 6 | C9: 6 | D9: 2.08 | E9: 0 | G9: Mock | H9: Height (soil - veg. point) | I9: Length of 2nd true leaf in cm | J9: Weight in g | K9: Hypocotyl discoloration
A10: 2 | B10: 7 | C10: 7.5 | D10: 3.93 | E10: 0
A11: 3 | B11: 7 | C11: 6.5 | D11: 3.1 | E11: 0 | G11: min | H11: =B39-B40 -> 6.5974157 | I11: =C39-C40 -> 6.1389231 | J11: =D39-D40 -> 2.5132533 | K11: =E39-E40 -> 0
A12: 4 | B12: 8 | C12: 7.5 | D12: 3.04 | E12: 0 | G12: max | H12: =B39+B40 -> 10.102584 | I12: =C39+C40 -> 7.6944102 | J12: =D39+D40 -> 4.3634133 | K12: =E39+E40 -> 0
A13: 5 | B13: 9 | C13: 6.5 | D13: 2.6 | E13: 0
A14: 6 | B14: 8.5 | C14: 6 | D14: 4.06 | E14: 0
A15: 7 | B15: 7.5 | C15: 7.5 | D15: 3.44 | E15: 0
A16: 8 | B16: 8 | C16: 7.5 | D16: 4.06 | E16: 0
A17: 9 | B17: 8.5 | C17: 7.5 | D17: 3.5 | E17: 0
A18: 10 | B18: 8 | C18: 7 | D18: 3.02 | E18: 0
A19: 11 | B19: 5.5 | C19: 5 | D19: 0.88 | E19: 0
A20: 12 | B20: 8.5 | C20: 6.5 | D20: 4.14 | E20: 0
A21: 13 | B21: 7.5 | C21: 7.5 | D21: 2.73 | E21: 0
A22: 14 | B22: 7.5 | C22: 7 | D22: 3.31 | E22: 0
A23: 15 | B23: 6 | C23: 5 | D23: 1.86 | E23: 0
A24: 16 | B24: 9 | C24: 7 | D24: 3.25 | E24: 0
... A38: 30 | B38: 8.5 | C38: 8 | D38: 3.55 | E38: 0
A39: mean | B39: =AVERAGE(B9:B38) -> 8.35 | C39: =AVERAGE(C9:C38) -> 6.9166667 | D39: =AVERAGE(D9:D38) -> 3.4383333 | E39: =AVERAGE(E9:E38) -> 0 | F39: n
A40: Standardabweichung | B40: =STDEV(B9:B38) -> 1.7525843 | C40: =STDEV(C9:C38) -> 0.77774357 | D40: =STDEV(D9:D38) -> 0.92507999 | E40: =STDEV(E9:E38) -> 0 | F40: 15
A43: MOCK B | B43: Height (soil - veg. point) | C43: Length of longest leaf in cm | D43: Weight in g | E43: Hypocotyl discoloration
A44: Replikat
A45: 1 | B45: 9 | C45: 7 | D45: 3.25 | E45: 0
A46: 2 | B46: 8.5 | C46: 7.5 | D46: 3.8 | E46: 0
A47: 3 | B47: 7.5 | C47: 7.5 | D47: 3.47 | E47: 0
A48: 4 | B48: 8.5 | C48: 6 | D48: 3.84 | E48: 0
A49: 5 | B49: 9.5 | C49: 7 | D49: 4.23 | E49: 0
A50: 6 | B50: 8 | C50: 7 | D50: 3.37 | E50: 0
A51: 7 | B51: 8.5 | C51: 8 | D51: 4.12 | E51: 0
A52: 8 | B52: 11 | C52: 7.5 | D52: 4.3 | E52: 0
A53: 9 | B53: 12 | C53: 7 | D53: 4.46 | E53: 0
A54: 10 | B54: 6 | C54: 6 | D54: 1.68 | E54: 0
A55: 11 | B55: 9.5 | C55: 6.5 | D55: 3.56 | E55: 0
A56: 12 | B56: 14 | C56: 7.5 | D56: 5.13 | E56: 0
...

Sheet Summary
A1: ='Tabelle 1'!A1 -> V. dahliae - plant experiment with | H1: ='Tabelle 1'!#REF! -> #REF!
A2: ='Tabelle 1'!A3 -> Infection on (infected 10 day-old seedlings)
A3: ='Tabelle 1'!A4 -> date of measurement:
B5: ='Tabelle 1'!A7 -> MOCK A | C5: ='Tabelle 1'!A43 -> MOCK B | D5: ='Tabelle 1'!A64 -> WT A | E5: ='Tabelle 1'!A85 -> WT B | F5: ='Tabelle 1'!A106 -> ΔNML1 c8 | G5: ='Tabelle 1'!A127 -> ΔNML1 c9 | H5: ='Tabelle 1'!A148 -> ΔAML1 c2 | I5: ='Tabelle 1'!A169 -> ΔAML1 c3 | J5: ='Tabelle 1'!A190 -> AML1-NoGFP c2 | K5: ='Tabelle 1'!A211 -> AML1-NoGFP c10 | L5: ='Tabelle 1'!A232 -> AML1-GFP c12 | M5: ='Tabelle 1'!A253 -> AML1-GFP c14
A6: Height of plant (soil - veg. point) | B6: ='Tabelle 1'!B39 -> 8.35 | C6: ='Tabelle 1'!B60 -> 9.2 | D6: ='Tabelle 1'!B81 -> 4.1333333 | E6: ='Tabelle 1'!B102 -> 5.0333333 | F6: ='Tabelle 1'!B123 -> 6.7 | G6: ='Tabelle 1'!B144 -> 6.4642857 | H6: ='Tabelle 1'!B165 -> 6.1666667 | I6: ='Tabelle 1'!B186 -> 6.7 | J6: ='Tabelle 1'!B207 -> 4.9333333 | K6: ='Tabelle 1'!B228 -> 4.7666667 | L6: ='Tabelle 1'!B249 -> 5.9133333 | M6: ='Tabelle 1'!B270 -> 6.0666667
B7: ='Tabelle 1'!B40 -> 1.7525843 | C7: ='Tabelle 1'!B61 -> 1.9346465 | D7: ='Tabelle 1'!B82 -> 1.4816336 | E7: ='Tabelle 1'!B103 -> 0.85495753 | F7: ='Tabelle 1'!B124 -> 1.2789505 | G7: ='Tabelle 1'!B145 -> 1.2628461 | H7: ='Tabelle 1'!B166 -> 1.6109743 | I7: ='Tabelle 1'!B187 -> 0.6761234 | J7: ='Tabelle 1'!B208 -> 1.5453463 | K7: ='Tabelle 1'!B229 -> 1.412529 | L7: ='Tabelle 1'!B250 -> 1.2094076 | M7: ='Tabelle 1'!B271 -> 1.6460631
A8: Length of longest true leaf in cm | B8: ='Tabelle 1'!C39 -> 6.9166667 | C8: ='Tabelle 1'!C60 -> 7.1333333 | D8: ='Tabelle 1'!C81 -> 4.0333333 | E8: ='Tabelle 1'!C102 -> 4.8333333 | F8: ='Tabelle 1'!C123 -> 5.7333333 | G8: ='Tabelle 1'!C144 -> 6.1785714 | H8: ='Tabelle 1'!C165 -> 5.1333333 | I8: ='Tabelle 1'!C186 -> 6.0666667 | J8: ='Tabelle 1'!C207 -> 4.7333333 | K8: ='Tabelle 1'!C228 -> 4.3333333 | L8: ='Tabelle 1'!C249 -> 5.5 | M8: ='Tabelle 1'!C270 -> 5.2666667
B9: ='Tabelle 1'!C40 -> 0.77774357 | C9: ='Tabelle 1'!C61 -> 0.61139964 | D9: ='Tabelle 1'!C82 -> 1.1254629 | E9: ='Tabelle 1'!C103 -> 0.9940298 | F9: ='Tabelle 1'!C124 -> 0.97955286 | G9: ='Tabelle 1'!C145 -> 0.91161612 | H9: ='Tabelle 1'!C166 -> 0.91547542 | I9: ='Tabelle 1'!C187 -> 1.1317917 | J9: ='Tabelle 1'!C208 -> 1.0327956 | K9: ='Tabelle 1'!C229 -> 1.2909944 | L9: ='Tabelle 1'!C250 -> 0.75592895 | M9: ='Tabelle 1'!C271 -> 1.0153583
A10: Weight in g | B10: ='Tabelle 1'!D39 -> 3.4383333 | C10: ='Tabelle 1'!D60 -> 3.8266667 | D10: ='Tabelle 1'!D81 -> 1.0086667 | E10: ='Tabelle 1'!D102 -> 1.4893333 | F10: ='Tabelle 1'!D123 -> 2.0226667 | G10: ='Tabelle 1'!D144 -> 2.12 | H10: ='Tabelle 1'!D165 -> 1.72 | I10: ='Tabelle 1'!D186 -> 2.3973333 | J10: ='Tabelle 1'!D207 -> 1.616 | K10: ='Tabelle 1'!D228 -> 1.4153333 | L10: ='Tabelle 1'!D249 -> 2.0753333 | M10: ='Tabelle 1'!D270 -> 2.1173333
B11: ='Tabelle 1'!D40 -> 0.92507999 | C11: ='Tabelle 1'!D61 -> 0.77892478 | D11: ='Tabelle 1'!D82 -> 0.74631348 | E11: ='Tabelle 1'!D103 -> 0.59175848 | F11: ='Tabelle 1'!D124 -> 0.71524688 | G11: ='Tabelle 1'!D145 -> 0.75094812 | H11: ='Tabelle 1'!D166 -> 0.74820738 | I11: ='Tabelle 1'!D187 -> 0.79145857 | J11: ='Tabelle 1'!D208 -> 1.0244218 | K11: ='Tabelle 1'!D229 -> 0.93552023 | L11: ='Tabelle 1'!D250 -> 0.58008456 | M11: ='Tabelle 1'!D271 -> 0.82098779
A12: Hypocotyl Discoloration | B12: ='Tabelle 1'!E39 -> 0 | C12: ='Tabelle 1'!E60 -> 0 | D12: ='Tabelle 1'!E81 -> 1 | E12: ='Tabelle 1'!E102 -> 0.96666667 | F12: ='Tabelle 1'!E123 -> 0.8 | G12: ='Tabelle 1'!E144 -> 0.96428571 | H12: ='Tabelle 1'!E165 -> 0.96666667 | I12: ='Tabelle 1'!E186 -> 0.8 | J12: ='Tabelle 1'!E207 -> 0.86666667 | K12: ='Tabelle 1'!E228 -> 1 | L12: ='Tabelle 1'!E249 -> 0.76666667 | M12: ='Tabelle 1'!E270 -> 0.83333333
B13: ='Tabelle 1'!E40 -> 0 | C13: ='Tabelle 1'!E61 -> 0 | D13: ='Tabelle 1'!E82 -> 0 | E13: ='Tabelle 1'!E103 -> 0.12909944 | F13: ='Tabelle 1'!E124 -> 0.41403934 | G13: ='Tabelle 1'!E145 -> 0.13363062 | H13: ='Tabelle 1'!E166 -> 0.12909944 | I13: ='Tabelle 1'!E187 -> 0.3683942 | J13: ='Tabelle 1'!E208 -> 0.35186578 | K13: ='Tabelle 1'!E229 -> 0 | L13: ='Tabelle 1'!E250 -> 0.41690469 | M13: ='Tabelle 1'!E271 -> 0.36187343
A14: n | B14: ='Tabelle 1'!F40 -> 15 | C14: ='Tabelle 1'!F61 -> 15 | D14: ='Tabelle 1'!F82 -> 15 | E14: ='Tabelle 1'!F103 -> 15 | F14: ='Tabelle 1'!F124 -> 15 | G14: ='Tabelle 1'!F145 -> 15 | H14: ='Tabelle 1'!F166 -> 15 | I14: ='Tabelle 1'!F187 -> 15 | J14: ='Tabelle 1'!F208 -> 15 | K14: ='Tabelle 1'!F229 -> 15 | L14: ='Tabelle 1'!F250 -> 15 | M14: ='Tabelle 1'!F271 -> 15
I16: T-Test
I18: Plant size
I25: Length of 2nd true leaf in cm
I38: Weight in g

Sheet Degree of Symptoms
A1: ='Tabelle 1'!A1 -> V. dahliae - plant experiment with | I1: ='Tabelle 1'!#REF! -> #REF!
A2: ='Tabelle 1'!A2 -> spore conc. 1x10^7 Sp/ml, infection 40 min root dipping while shaking (35 rpm)
A3: ='Tabelle 1'!A3 -> Infection on (infected 10 day-old seedlings)
A4: ='Tabelle 1'!A4 -> date of measurement:
A8: Height | B8: Symptoms | C8: % | E8: Use Mock mean values as 100% | H8: Degree
B9: dead | C9: 0 | F9: =C9 -> 0 | G9: 0 | H9: 5 | J9: 0 | K9: 5 | L9: das ist die Matrix, mit der verglichen wird. Die Reihenfolge der Größe muss aufsteigend sein
B10: very strong | C10: 0.1 | E10: 39 | F10: =0.001*G13 -> 0.00835 | G10: =0.39*G13 -> 3.2565 | H10: 4 | J10: =F10 -> 0.00835 | K10: 4 | L10: Das Ergebnis habe ich in Tabelle1 bei stem assay reingeschrieben.
B11: strong | C11: 40 | D11: - | E11: 59 | F11: =0.4*G13 -> 3.34 | G11: =0.59*G13 -> 4.9265 | H11: 3 | J11: =F11 -> 3.34 | K11: 3
B12: weak | C12: 60 | D12: - | E12: 79 | F12: =0.6*G13 -> 5.01 | G12: =0.79*G13 -> 6.5965 | H12: 2 | J12: =F12 -> 5.01 | K12: 2
B13: healthy | C13: 80 | D13: - | E13: 100 | F13: =0.8*G13 -> 6.68 | G13: ='Tabelle 1'!B39 -> 8.35 | H13: 1 | J13: =F13 -> 6.68 | K13: 1
A17: Leaf | B17: Symptoms | C17: % | E17: Use Mock mean values as 100% | H17: Degree
B18: dead | C18: 0 | F18: =C18 -> 0 | H18: 5 | J18: =F18 -> 0 | K18: =H18 -> 5
B19: very strong | C19: 0.1 | E19: 39 | F19: =0.001*G22 -> 0.0069166667 | G19: =0.39*G22 -> 2.6975 | H19: 4 | J19: =F19 -> 0.0069166667 | K19: =H19 -> 4
B20: strong | C20: 40 | D20: - | E20: 59 | F20: =0.4*G22 -> 2.7666667 | G20: =0.59*G22 -> 4.0808333 | H20: 3 | J20: =F20 -> 2.7666667 | K20: =H20 -> 3
B21: weak | C21: 60 | D21: - | E21: 79 | F21: =0.6*G22 -> 4.15 | G21: =0.79*G22 -> 5.4641667 | H21: 2 | J21: =F21 -> 4.15 | K21: =H21 -> 2
B22: healthy | C22: 80 | D22: - | E22: 100 | F22: =0.8*G22 -> 5.5333333 | G22: ='Tabelle 1'!C39 -> 6.9166667 | H22: 1 | J22: =F22 -> 5.5333333 | K22: =H22 -> 1
A25: Weight | B25: Symptoms | C25: % | E25: Use Mock mean values as 100% | H25: Degree
B26: dead | C26: 0 | F26: =C26 -> 0 | H26: 5 | J26: =F26 -> 0 | K26: =H26 -> 5
B27: very strong | C27: 0.1 | E27: 39 | F27: =0.01*$G$30 -> 0.034383333 | G27: =0.39*$G$30 -> 1.34095 | H27: 4 | J27: =F27 -> 0.034383333 | K27: =H27 -> 4
B28: strong | C28: 40 | D28: - | E28: 59 | F28: =0.4*$G$30 -> 1.3753333 | G28: =0.59*$G$30 -> 2.0286167 | H28: 3 | J28: =F28 -> 1.3753333 | K28: =H28 -> 3
B29: weak | C29: 60 | D29: - | E29: 79 | F29: =0.6*$G$30 -> 2.063 | G29: =0.79*$G$30 -> 2.7162833 | H29: 2 | J29: =F29 -> 2.063 | K29: =H29 -> 2
B30: healthy | C30: 80 | D30: - | E30: 100 | F30: =0.8*$G$30 -> 2.7506667 | G30: ='Tabelle 1'!D39 -> 3.4383333 | H30: 1 | J30: =F30 -> 2.7506667 | K30: =H30 -> 1

Sheet Tabelle1 (2)
A1: ='Tabelle 1'!A7 -> MOCK A | B1: Höhe | C1: Blattgröße | D1: Gewicht | E1: zusammen | H1: Anzahl | M1: MOCK | N1: WT | O1: ΔNML1 | P1: ΔAML1 | Q1: Comp.AML1 | R1: AML1-GFP
A2: 1 | B2: =VLOOKUP('Tabelle 1'!B9,'Degree of Symptoms'!$J$9:$K$13,2) -> 2 | C2: =VLOOKUP('Tabelle 1'!C9,'Degree of Symptoms'!$J$13:$K$22,2) -> 1 | D2: =VLOOKUP('Tabelle 1'!D9,'Degree of Symptoms'!$J$26:$K$30,2) -> 2 | E2: =AVERAGE(B2:D2) -> 1.6666667 | G2: 1-1,99 | H2: =COUNTIFS($E$2:$E$16,"<1,99",$E$2:$E$16,">=1") -> 13 | J2: 1-1,99 | L2: healthy | M2: =27+M13 -> 53 | N2: 3 | O2: =14+P13 -> 22 | P2: =13+O13 -> 24 | Q2: 6 | R2: 13
A3: 2 | B3: =VLOOKUP('Tabelle 1'!B10,'Degree of Symptoms'!$J$9:$K$13,2) -> 1 | C3: =VLOOKUP('Tabelle 1'!C10,'Degree of Symptoms'!$J$13:$K$22,2) -> 1 | D3: =VLOOKUP('Tabelle 1'!D10,'Degree of Symptoms'!$J$26:$K$30,2) -> 1 | E3: =AVERAGE(B3:D3) -> 1 | G3: 2-2,99 | H3: =COUNTIFS($E$2:$E$16,"<2,99",$E$2:$E$16,">=2") -> 2 | J3: 2-2,99 | L3: weak symptoms | M3: 4 | N3: =11+N14 -> 19 | O3: =11+P14 -> 20 | P3: =14+O14 -> 22 | Q3: 7 | R3: 11
A4: 3 | B4: =VLOOKUP('Tabelle 1'!B11,'Degree of Symptoms'!$J$9:$K$13,2) -> 1 | C4: =VLOOKUP('Tabelle 1'!C11,'Degree of Symptoms'!$J$13:$K$22,2) -> 1 | D4: =VLOOKUP('Tabelle 1'!D11,'Degree of Symptoms'!$J$26:$K$30,2) -> 1 | E4: =AVERAGE(B4:D4) -> 1 | G4: 3-3,99 | H4: =COUNTIFS($E$2:$E$16,"<3,99",$E$2:$E$16,">=3") -> 0 | J4: 3-3,99 | L4: strong symptoms | M4: 1 | N4: =16+N15 -> 29 | O4: =4+P15 -> 16 | P4: 10 | Q4: 16 | R4: 6
A5: 4 | B5: =VLOOKUP('Tabelle 1'!B12,'Degree of Symptoms'!$J$9:$K$13,2) -> 1 | C5: =VLOOKUP('Tabelle 1'!C12,'Degree of Symptoms'!$J$13:$K$22,2) -> 1 | D5: =VLOOKUP('Tabelle 1'!D12,'Degree of Symptoms'!$J$26:$K$30,2) -> 1 | E5: =AVERAGE(B5:D5) -> 1 | G5: 4-4,99 | H5: =COUNTIFS($E$2:$E$16,"<4,99",$E$2:$E$16,">=4") -> 0 | J5: 4-4,99 | L5: very strong symptoms | M5: =H5 -> 0 | N5: =H47+N16 -> 7 | O5: =H89 -> 0 | P5: 4 | Q5: 1 | R5: =H215 -> 0
A6: 5 | B6: =VLOOKUP('Tabelle 1'!B13,'Degree of Symptoms'!$J$9:$K$13,2) -> 1 | C6: =VLOOKUP('Tabelle 1'!C13,'Degree of Symptoms'!$J$13:$K$22,2) -> 1 | D6: =VLOOKUP('Tabelle 1'!D13,'Degree of Symptoms'!$J$26:$K$30,2) -> 2 | E6: =AVERAGE(B6:D6) -> 1.3333333 | G6: 5 | H6: =COUNTIF($E$2:$E$16,">=5") -> 0 | J6: 5 | L6: dead | M6: =H6 -> 0 | N6: =H48 -> 0 | O6: =H90 -> 0 | P6: =H132 -> 0 | Q6: =H174 -> 0 | R6: =H216 -> 0
A7: 6 | B7: =VLOOKUP('Tabelle 1'!B14,'Degree of Symptoms'!$J$9:$K$13,2) -> 1 | C7: =VLOOKUP('Tabelle 1'!C14,'Degree of Symptoms'!$J$13:$K$22,2) -> 1 | D7: =VLOOKUP('Tabelle 1'!D14,'Degree of Symptoms'!$J$26:$K$30,2) -> 1 | E7: =AVERAGE(B7:D7) -> 1 | H7: =SUM(H2:H6) -> 15
A8: 7 | B8: =VLOOKUP('Tabelle 1'!B15,'Degree of Symptoms'!$J$9:$K$13,2) -> 1 | C8: =VLOOKUP('Tabelle 1'!C15,'Degree of Symptoms'!$J$13:$K$22,2) -> 1 | D8: =VLOOKUP('Tabelle 1'!D15,'Degree of Symptoms'!$J$26:$K$30,2) -> 1 | E8: =AVERAGE(B8:D8) -> 1 | L8: n | M8: =SUM(M2:M6) -> 58 | N8: =SUM(N2:N6) -> 58 | O8: =SUM(O2:O6) -> 58 | P8: =SUM(P2:P6) -> 60 | Q8: =SUM(Q2:Q6) -> 30 | R8: =SUM(R2:R6) -> 30
A9: 8 | B9: =VLOOKUP('Tabelle 1'!B16,'Degree of Symptoms'!$J$9:$K$13,2) -> 1 | C9: =VLOOKUP('Tabelle 1'!C16,'Degree of Symptoms'!$J$13:$K$22,2) -> 1 | D9: =VLOOKUP('Tabelle 1'!D16,'Degree of Symptoms'!$J$26:$K$30,2) -> 1 | E9: =AVERAGE(B9:D9) -> 1
A10: 9 | B10: =VLOOKUP('Tabelle 1'!B17,'Degree of Symptoms'!$J$9:$K$13,2) -> 1 | C10: =VLOOKUP('Tabelle 1'!C17,'Degree of Symptoms'!$J$13:$K$22,2) -> 1 | D10: =VLOOKUP('Tabelle 1'!D17,'Degree of Symptoms'!$J$26:$K$30,2) -> 1 | E10: =AVERAGE(B10:D10) -> 1
A11: 10 | B11: =VLOOKUP('Tabelle 1'!B18,'Degree of Symptoms'!$J$9:$K$13,2) -> 1 | C11: =VLOOKUP('Tabelle 1'!C18,'Degree of Symptoms'!$J$13:$K$22,2) -> 1 | D11: =VLOOKUP('Tabelle 1'!D18,'Degree of Symptoms'!$J$26:$K$30,2) -> 1 | E11: =AVERAGE(B11:D11) -> 1
A12: 11 | B12: =VLOOKUP('Tabelle 1'!B19,'Degree of Symptoms'!$J$9:$K$13,2) -> 2 | C12: =VLOOKUP('Tabelle 1'!C19,'Degree of Symptoms'!$J$13:$K$22,2) -> 2 | D12: =VLOOKUP('Tabelle 1'!D19,'Degree of Symptoms'!$J$26:$K$30,2) -> 4 | E12: =AVERAGE(B12:D12) -> 2.6666667 | L12: Second repetition Julia's mutants | M12: MOCK | N12: WT | O12: ΔAML1 | P12: ΔNML1
A13: 12 | B13: =VLOOKUP('Tabelle 1'!B20,'Degree of Symptoms'!$J$9:$K$13,2) -> 1 | C13: =VLOOKUP('Tabelle 1'!C20,'Degree of Symptoms'!$J$13:$K$22,2) -> 1 | D13: =VLOOKUP('Tabelle 1'!D20,'Degree of Symptoms'!$J$26:$K$30,2) -> 1 | E13: =AVERAGE(B13:D13) -> 1 | M13: 26 | N13: 2 | O13: 11 | P13: 8
A14: 13 | B14: =VLOOKUP('Tabelle 1'!B21,'Degree of Symptoms'!$J$9:$K$13,2) -> 1 | C14: =VLOOKUP('Tabelle 1'!C21,'Degree of Symptoms'!$J$13:$K$22,2) -> 1 | D14: =VLOOKUP('Tabelle 1'!D21,'Degree of Symptoms'!$J$26:$K$30,2) -> 2 | E14: =AVERAGE(B14:D14) -> 1.3333333 | M14: 1 | N14: 8 | O14: 8 | P14: 9
A15: 14 | B15: =VLOOKUP('Tabelle 1'!B22,'Degree of Symptoms'!$J$9:$K$13,2) -> 1 | C15: =VLOOKUP('Tabelle 1'!C22,'Degree of Symptoms'!$J$13:$K$22,2) -> 1 | D15: =VLOOKUP('Tabelle 1'!D22,'Degree of Symptoms'!$J$26:$K$30,2) -> 1 | E15: =AVERAGE(B15:D15) -> 1 | M15: 1 | N15: 13 | O15: 7 | P15: 12
A16: 15 | B16: =VLOOKUP('Tabelle 1'!B23,'Degree of Symptoms'!$J$9:$K$13,2) -> 2 | C16: =VLOOKUP('Tabelle 1'!C23,'Degree of Symptoms'!$J$13:$K$22,2) -> 2 | D16: =VLOOKUP('Tabelle 1'!D23,'Degree of Symptoms'!$J$26:$K$30,2) -> 3 | E16: =AVERAGE(B16:D16) -> 2.3333333 | M16: 0 | N16: 5 | O16: 4 | P16: 0
F17: n | M17: 0 | N17: 0 | O17: 0 | P17: 0
A18: Mittelwert | B18: =AVERAGE(B2:B16) -> 1.2 | C18: =AVERAGE(C2:C16) -> 1.1333333 | D18: =AVERAGE(D2:D16) -> 1.5333333 | E18: =AVERAGE(E2:E16) -> 1.2888889 | F18: ='Tabelle 1'!F40 -> 15
A19: Fehler | B19: =STDEV(B2:B16) -> 0.41403934 | C19: =STDEV(C2:C16) -> 0.35186578 | D19: =STDEV(D2:D16) -> 0.91547542 | E19: =STDEV(E2:E16) -> 0.53253909 | M19: 28 | N19: 28 | O19: 30 | P19: 29
A22: ='Tabelle 1'!A43 -> MOCK B | B22: Höhe | C22: Blattgröße | D22: Gewicht | E22: zusammen | H22: Anzahl
A23: 1 | B23: =VLOOKUP('Tabelle 1'!B45,'Degree of Symptoms'!$J$9:$K$13,2) -> 1 | C23: =VLOOKUP('Tabelle 1'!C45,'Degree of Symptoms'!$J$13:$K$22,2) -> 1 | D23: =VLOOKUP('Tabelle 1'!D45,'Degree of Symptoms'!$J$26:$K$30,2) -> 1 | E23: =AVERAGE(B23:D23) -> 1 | G23: 1-1,99 | H23: =COUNTIFS($E$23:$E$37,"<1,99",$E$23:$E$37,">=1") -> 14
A24: 2 | B24: =VLOOKUP('Tabelle 1'!B46,'Degree of Symptoms'!$J$9:$K$13,2) -> 1 | C24: =VLOOKUP('Tabelle 1'!C46,'Degree of Symptoms'!$J$13:$K$22,2) -> 1 | D24: =VLOOKUP('Tabelle 1'!D46,'Degree of Symptoms'!$J$26:$K$30,2) -> 1 | E24: =AVERAGE(B24:D24) -> 1 | G24: 2-2,99 | H24: =COUNTIFS($E$23:$E$37,"<2,99",$E$23:$E$37,">=2") -> 1
A25: 3 | B25: =VLOOKUP('Tabelle 1'!B47,'Degree of Symptoms'!$J$9:$K$13,2) -> 1 | C25: =VLOOKUP('Tabelle 1'!C47,'Degree of Symptoms'!$J$13:$K$22,2) -> 1 | D25: =VLOOKUP('Tabelle 1'!D47,'Degree of Symptoms'!$J$26:$K$30,2) -> 1 | E25: =AVERAGE(B25:D25) -> 1 | G25: 3-3,99 | H25: =COUNTIFS($E$23:$E$37,"<3,99",$E$23:$E$37,">=3") -> 0
A26: 4 | B26: =VLOOKUP('Tabelle 1'!B48,'Degree of Symptoms'!$J$9:$K$13,2) -> 1 | C26: =VLOOKUP('Tabelle 1'!C48,'Degree of Symptoms'!$J$13:$K$22,2) -> 1 | D26: =VLOOKUP('Tabelle 1'!D48,'Degree of Symptoms'!$J$26:$K$30,2) -> 1 | E26: =AVERAGE(B26:D26) -> 1 | G26: 4-4,99 | H26: =COUNTIFS($E$23:$E$37,"<4,99",$E$23:$E$37,">=4") -> 0
A27: 5 | B27: =VLOOKUP('Tabelle 1'!B49,'Degree of Symptoms'!$J$9:$K$13,2) -> 1 | C27: =VLOOKUP('Tabelle 1'!C49,'Degree of Symptoms'!$J$13:$K$22,2) -> 1 | D27: =VLOOKUP('Tabelle 1'!D49,'Degree of Symptoms'!$J$26:$K$30,2) -> 1 | E27: =AVERAGE(B27:D27) -> 1 | G27: 5 | H27: =COUNTIF($E$23:$E$37,">=5") -> 0
A28: 6 | B28: =VLOOKUP('Tabelle 1'!B50,'Degree of Symptoms'!$J$9:$K$13,2) -> 1 | C28: =VLOOKUP('Tabelle 1'!C50,'Degree of Symptoms'!$J$13:$K$22,2) -> 1 | D28: =VLOOKUP('Tabelle 1'!D50,'Degree of Symptoms'!$J$26:$K$30,2) -> 1 | E28: =AVERAGE(B28:D28) -> 1 | H28: =SUM(H23:H27) -> 15
A29: 7 | B29: =VLOOKUP('Tabelle 1'!B51,'Degree of Symptoms'!$J$9:$K$13,2) -> 1 | C29: =VLOOKUP('Tabelle 1'!C51,'Degree of Symptoms'!$J$13:$K$22,2) -> 1 | D29: =VLOOKUP('Tabelle 1'!D51,'Degree of Symptoms'!$J$26:$K$30,2) -> 1 | E29: =AVERAGE(B29:D29) -> 1
A30: 8 | B30: =VLOOKUP('Tabelle 1'!B52,'Degree of Symptoms'!$J$9:$K$13,2) -> 1 | C30: =VLOOKUP('Tabelle 1'!C52,'Degree of Symptoms'!$J$13:$K$22,2) -> 1 | D30: =VLOOKUP('Tabelle 1'!D52,'Degree of Symptoms'!$J$26:$K$30,2) -> 1 | E30: =AVERAGE(B30:D30) -> 1
A31: 9 | B31: =VLOOKUP('Tabelle 1'!B53,'Degree of Symptoms'!$J$9:$K$13,2) -> 1 | C31: =VLOOKUP('Tabelle 1'!C53,'Degree of Symptoms'!$J$13:$K$22,2) -> 1 | D31: =VLOOKUP('Tabelle 1'!D53,'Degree of Symptoms'!$J$26:$K$30,2) -> 1 | E31: =AVERAGE(B31:D31) -> 1
A32: 10 | B32: =VLOOKUP('Tabelle 1'!B54,'Degree of Symptoms'!$J$9:$K$13,2) -> 2 | C32: =VLOOKUP('Tabelle 1'!C54,'Degree of Symptoms'!$J$13:$K$22,2) -> 1 | D32: =VLOOKUP('Tabelle 1'!D54,'Degree of Symptoms'!$J$26:$K$30,2) -> 3 | E32: =AVERAGE(B32:D32) -> 2
A33: 11 | B33: =VLOOKUP('Tabelle 1'!B55,'Degree of Symptoms'!$J$9:$K$13,2) -> 1 | C33: =VLOOKUP('Tabelle 1'!C55,'Degree of Symptoms'!$J$13:$K$22,2) -> 1 | D33: =VLOOKUP('Tabelle 1'!D55,'Degree of Symptoms'!$J$26:$K$30,2) -> 1 | E33: =AVERAGE(B33:D33) -> 1
A34: 12 | B34: =VLOOKUP('Tabelle 1'!B56,'Degree of Symptoms'!$J$9:$K$13,2) -> 1 | C34: =VLOOKUP('Tabelle 1'!C56,'Degree of Symptoms'!$J$13:$K$22,2) -> 1 | D34: =VLOOKUP('Tabelle 1'!D56,'Degree of Symptoms'!$J$26:$K$30,2) -> 1 | E34: =AVERAGE(B34:D34) -> 1
A35: 13 | B35: =VLOOKUP('Tabelle 1'!B57,'Degree of Symptoms'!$J$9:$K$13,2) -> 1 | C35: =VLOOKUP('Tabelle 1'!C57,'Degree of Symptoms'!$J$13:$K$22,2) -> 1 | D35: =VLOOKUP('Tabelle 1'!D57,'Degree of Symptoms'!$J$26:$K$30,2) -> 1 | E35: =AVERAGE(B35:D35) -> 1
A36: 14 | B36: =VLOOKUP('Tabelle 1'!B58,'Degree of Symptoms'!$J$9:$K$13,2) -> 1 | C36: =VLOOKUP('Tabelle 1'!C58,'Degree of Symptoms'!$J$13:$K$22,2) -> 1 | D36: =VLOOKUP('Tabelle 1'!D58,'Degree of Symptoms'!$J$26:$K$30,2) -> 1 | E36: =AVERAGE(B36:D36) -> 1
A37: 15 | B37: =VLOOKUP('Tabelle 1'!B59,'Degree of Symptoms'!$J$9:$K$13,2) -> 1 | C37: =VLOOKUP('Tabelle 1'!C59,'Degree of Symptoms'!$J$13:$K$22,2) -> 1 | D37: =VLOOKUP('Tabelle 1'!D59,'Degree of Symptoms'!$J$26:$K$30,2) -> 1 | E37: =AVERAGE(B37:D37) -> 1
F38: n
A39: Mittelwert | B39: =AVERAGE(B23:B37) -> 1.0666667 | C39: =AVERAGE(C23:C37) -> 1 | D39: =AVERAGE(D23:D37) -> 1.1333333 | E39: =AVERAGE(E23:E37) -> 1.0666667 | F39: ='Tabelle 1'!F61 -> 15
A40: Fehler | B40: =STDEV(B23:B37) -> 0.25819889 | C40: =STDEV(C23:C37) -> 0 | D40: =STDEV(D23:D37) -> 0.51639778 | E40: =STDEV(E23:E37) -> 0.25819889
A43: ='Tabelle 1'!A64 -> WT A | B43: Höhe | C43: Blattgröße | D43: Gewicht | E43: zusammen | H43: Anzahl
A44: 1 | B44: =VLOOKUP('Tabelle 1'!B66,'Degree of Symptoms'!$J$9:$K$13,2) -> 4 | C44: =VLOOKUP('Tabelle 1'!C66,'Degree of Symptoms'!$J$13:$K$22,2) -> 3 | D44: =VLOOKUP('Tabelle 1'!D66,'Degree of Symptoms'!$J$26:$K$30,2) -> 4 | E44: =AVERAGE(B44:D44) -> 3.6666667 | G44: 1-1,99 | H44: =COUNTIFS($E$44:$E$58,"<1,99",$E$44:$E$58,">=1") -> 0
...

Sheet Diagramm4

Sheet PARA ESTADÍSTICA
K1: treatments | L1: rank | Q1: MOCK | R1: WT | S1: ΔAML1 | T1: Comp.AML1 | U1: AML1.GFP
C2: MOCK | D2: WT | E2: ΔAML1 | F2: Comp.AML1 | G2: AML1-GFP | K2: MOCK | L2: 1 | O2: 1 | P2: healthy | Q2: =C3/C$9 -> 0.9137931 | R2: =D3/D$9 -> 0.051724138 | S2: =E3/E$9 -> 0.4 | T2: =F3/F$9 -> 0.2 | U2: =G3/G$9 -> 0.43333333
A3: 1 | B3: healthy | C3: 53 | D3: 3 | E3: 24 | F3: 6 | G3: 13 | K3: MOCK | L3: 1 | O3: 2 | P3: weak symptoms | Q3: =C4/C$9 -> 0.068965517 | R3: =D4/D$9 -> 0.32758621 | S3: =E4/E$9 -> 0.36666667 | T3: =F4/F$9 -> 0.23333333 | U3: =G4/G$9 -> 0.36666667
A4: 2 | B4: weak symptoms | C4: 4 | D4: 19 | E4: 22 | F4: 7 | G4: 11 | K4: MOCK | L4: 1 | O4: 3 | P4: strong symptoms | Q4: =C5/C$9 -> 0.017241379 | R4: =D5/D$9 -> 0.5 | S4: =E5/E$9 -> 0.16666667 | T4: =F5/F$9 -> 0.53333333 | U4: =G5/G$9 -> 0.2
A5: 3 | B5: strong symptoms | C5: 1 | D5: 29 | E5: 10 | F5: 16 | G5: 6 | K5: MOCK | L5: 1 | O5: 4 | P5: very strong symptoms | Q5: =C6/C$9 -> 0 | R5: =D6/D$9 -> 0.12068966 | S5: =E6/E$9 -> 0.066666667 | T5: =F6/F$9 -> 0.033333333 | U5: =G6/G$9 -> 0
A6: 4 | B6: very strong symptoms | C6: 0 | D6: 7 | E6: 4 | F6: 1 | G6: 0 | K6: MOCK | L6: 1
K7: MOCK | L7: 1 | P7: treatments | Q7: Percent | R7: rank
K8: MOCK | L8: 1 | P8: MOCK | Q8: 0.9137931 | R8: 1
B9: n | C9: 58 | D9: 58 | E9: 60 | F9: 30 | G9: 30 | K9: MOCK | L9: 1 | P9: MOCK | Q9: 0.068965517 | R9: 2
K10: MOCK | L10: 1 | P10: MOCK | Q10: 0.017241379 | R10: 3
K11: MOCK | L11: 1 | P11: MOCK | Q11: 0 | R11: 4
B12: MOCK | C12: 1 | D12: 1 | E12: 1 | F12: 1 | G12: 1 | K12: MOCK | L12: 1 | P12: WT | Q12: 0.051724138 | R12: 1
B13: MOCK | C13: 1 | D13: 1 | E13: 1 | F13: 1 | G13: 1 | K13: MOCK | L13: 1 | P13: WT | Q13: 0.32758621 | R13: 2
B14: MOCK | C14: 1 | D14: 1 | E14: 1 | F14: 1 | G14: 1 | K14: MOCK | L14: 1 | P14: WT | Q14: 0.5 | R14: 3
B15: MOCK | C15: 1 | D15: 2 | E15: 1 | F15: 1 | G15: 1 | K15: MOCK | L15: 1 | P15: WT | Q15: 0.12068966 | R15: 4
B16: MOCK | C16: 1 | D16: 2 | E16: 1 | F16: 1 | G16: 1 | K16: MOCK | L16: 1 | P16: ΔAML1 | Q16: 0.4 | R16: 1
B17: MOCK | C17: 1 | D17: 2 | E17: 1 | F17: 1 | G17: 1 | K17: MOCK | L17: 1 | P17: ΔAML1 | Q17: 0.36666667 | R17: 2
B18: MOCK | C18: 1 | D18: 2 | E18: 1 | F18: 2 | G18: 1 | K18: MOCK | L18: 1 | P18: ΔAML1 | Q18: 0.16666667 | R18: 3
B19: MOCK | C19: 1 | D19: 2 | E19: 1 | F19: 2 | G19: 1 | K19: MOCK | L19: 1 | P19: ΔAML1 | Q19: 0.066666667 | R19: 4
B20: MOCK | C20: 1 | D20: 2 | E20: 1 | F20: 2 | G20: 1 | K20: MOCK | L20: 1 | P20: Comp.AML1 | Q20: 0.2 | R20: 1
B21: MOCK | C21: 1 | D21: 2 | E21: 1 | F21: 2 | G21: 1 | K21: MOCK | L21: 1 | P21: Comp.AML1 | Q21: 0.23333333 | R21: 2
B22: MOCK | C22: 1 | D22: 2 | E22: 1 | F22: 2 | G22: 1 | K22: MOCK | L22: 1 | P22: Comp.AML1 | Q22: 0.53333333 | R22: 3
B23: MOCK | C23: 1 | D23: 2 | E23: 1 | F23: 2 | G23: 1 | K23: MOCK | L23: 1 | P23: Comp.AML1 | Q23: 0.033333333 | R23: 4
... B27: MOCK | C27: 1 | D27: 2 | E27: 1 | F27: 3 | G27: 2 | K27: MOCK | L27: 1 | P27: AML1.GFP | Q27: 0 | R27: 4
B28: MOCK | C28: 1 | D28: 2 | E28: 1 | F28: 3 | G28: 2 | K28: MOCK | L28: 1
B29: MOCK | C29: 1 | D29: 2 | E29: 1 | F29: 3 | G29: 2 | K29: MOCK | L29: 1
B30: MOCK | C30: 1 | D30: 2 | E30: 1 | F30: 3 | G30: 2 | K30: MOCK | L30: 1
B31: MOCK | C31: 1 | D31: 2 | E31: 1 | F31: 3 | G31: 2 | K31: MOCK | L31: 1
B32: MOCK | C32: 1 | D32: 2 | E32: 1 | F32: 3 | G32: 2 | K32: MOCK | L32: 1
B33: MOCK | C33: 1 | D33: 2 | E33: 1 | F33: 3 | G33: 2 | K33: MOCK | L33: 1
B34: MOCK | C34: 1 | D34: 3 | E34: 1 | F34: 3 | G34: 2 | K34: MOCK | L34: 1
B35: MOCK | C35: 1 | D35: 3 | E35: 1 | F35: 3 | G35: 2 | K35: MOCK | L35: 1
B36: MOCK | C36: 1 | D36: 3 | E36: 2 | F36: 3 | G36: 3 | K36: MOCK | L36: 1
B37: MOCK | C37: 1 | D37: 3 | E37: 2 | F37: 3 | G37: 3 | K37: MOCK | L37: 1
B38: MOCK | C38: 1 | D38: 3 | E38: 2 | F38: 3 | G38: 3 | K38: MOCK | L38: 1
B39: MOCK | C39: 1 | D39: 3 | E39: 2 | F39: 3 | G39: 3 | K39: MOCK | L39: 1
... B41: MOCK | C41: 1 | D41: 3 | E41: 2 | F41: 4 | G41: 3 | K41: MOCK | L41: 1
B42: MOCK | C42: 1 | D42: 3 | E42: 2 | K42: MOCK | L42: 1
B43: MOCK | C43: 1 | D43: 3 | E43: 2 | K43: MOCK | L43: 1
B44: MOCK | C44: 1 | D44: 3 | E44: 2 | K44: MOCK | L44: 1
...
