Workbook

Sheet Tabelle 1
A1: V. dahliae - plant experiment with | F1: Date
A2: spore conc. 1x10^7 Sp/ml, infection 40 min root dipping while shaking (35 rpm)
A3: Infection on (infected 10 day-old seedlings)
A4: date of measurement:
A5: Stem assay: 8 min EtOH, 8 min NaClO, 2 x H2O
A7: Mock | B7: Height (soil - veg. point) | C7: Length of longest leaf in cm | D7: Weight in g | E7: Hypocotyl discoloration | F7: Stem Assay
A8: Replikat
A9: 1 | H9: Mock | I9: Height (soil - veg. point) | J9: Length of 2nd true leaf in cm | K9: Weight in g | L9: Hypocotyl discoloration
A10: 2
A11: 3 | H11: min | I11: =B24-B25 -> #DIV/0! | J11: =C24-C25 -> #DIV/0! | K11: =D24-D25 -> #DIV/0! | L11: =E24-E25 -> #DIV/0!
A12: 4 | H12: max | I12: =B24+B25 -> #DIV/0! | J12: =C24+C25 -> #DIV/0! | K12: =D24+D25 -> #DIV/0! | L12: =E24+E25 -> #DIV/0!
A13: 5
A14: 6
A15: 7
A16: 8
A17: 9
A18: 10
A19: 11
A20: 12
A21: 13
A22: 14
A23: 15
A24: mean | B24: =AVERAGE(B9:B23) -> #DIV/0! | C24: =AVERAGE(C9:C23) -> #DIV/0! | D24: =AVERAGE(D9:D23) -> #DIV/0! | E24: =AVERAGE(E9:E23) -> #DIV/0! | F24: =AVERAGE(F9:F23) -> #DIV/0! | G24: n
A25: Standardabweichung | B25: =STDEV(B9:B23) -> #DIV/0! | C25: =STDEV(C9:C23) -> #DIV/0! | D25: =STDEV(D9:D23) -> #DIV/0! | E25: =STDEV(E9:E23) -> #DIV/0! | F25: =STDEV(F9:F23) -> #DIV/0! | G25: 15
A27: VGB39
A28: WT JR2 | B28: Height (soil - veg. point) | C28: Length of longest leaf in cm | D28: Weight in g | E28: Hypocotyl discoloration | F28: Stem Assay
A29: Replikat
A30: 1
A31: 2
A32: 3
A33: 4
A34: 5
A35: 6
A36: 7
A37: 8
A38: 9
A39: 10
A40: 11
A41: 12
... A44: 15
...

Sheet Summary
A1: ='Tabelle 1'!A1 -> V. dahliae - plant experiment with | H1: ='Tabelle 1'!F1 -> Date
A2: ='Tabelle 1'!A3 -> Infection on (infected 10 day-old seedlings)
A3: ='Tabelle 1'!A4 -> date of measurement:
B5: ='Tabelle 1'!A7 -> Mock | C5: ='Tabelle 1'!A28 -> WT JR2 | D5: ='Tabelle 1'!A51 -> 3 | E5: ='Tabelle 1'!A72 -> 4 | F5: ='Tabelle 1'!A93 -> 5 | G5: ='Tabelle 1'!A114 -> 6 | H5: ='Tabelle 1'!A135 -> 7 | I5: ='Tabelle 1'!A156 -> 8 | J5: ='Tabelle 1'!A177 -> 9 | K5: ='Tabelle 1'!A198 -> 10 | L5: ='Tabelle 1'!A219 -> 11 | M5: ='Tabelle 1'!A240 -> 12
A6: Height of plant (soil - veg. point) | B6: ='Tabelle 1'!B24 -> #DIV/0! | C6: ='Tabelle 1'!B45 -> #DIV/0! | D6: ='Tabelle 1'!B68 -> #DIV/0! | E6: ='Tabelle 1'!B89 -> #DIV/0! | F6: ='Tabelle 1'!B110 -> #DIV/0! | G6: ='Tabelle 1'!B131 -> #DIV/0! | H6: ='Tabelle 1'!B152 -> #DIV/0! | I6: ='Tabelle 1'!B173 -> #DIV/0! | J6: ='Tabelle 1'!B194 -> #DIV/0! | K6: ='Tabelle 1'!B215 -> #DIV/0! | L6: ='Tabelle 1'!B236 -> #DIV/0! | M6: ='Tabelle 1'!B257 -> #DIV/0!
B7: ='Tabelle 1'!B25 -> #DIV/0! | C7: ='Tabelle 1'!B46 -> #DIV/0! | D7: ='Tabelle 1'!B69 -> #DIV/0! | E7: ='Tabelle 1'!B90 -> #DIV/0! | F7: ='Tabelle 1'!B111 -> #DIV/0! | G7: ='Tabelle 1'!B132 -> #DIV/0! | H7: ='Tabelle 1'!B153 -> #DIV/0! | I7: ='Tabelle 1'!B174 -> #DIV/0! | J7: ='Tabelle 1'!B195 -> #DIV/0! | K7: ='Tabelle 1'!B216 -> #DIV/0! | L7: ='Tabelle 1'!B237 -> #DIV/0! | M7: ='Tabelle 1'!B258 -> #DIV/0!
A8: Length of longest true leaf in cm | B8: ='Tabelle 1'!C24 -> #DIV/0! | C8: ='Tabelle 1'!C45 -> #DIV/0! | D8: ='Tabelle 1'!C68 -> #DIV/0! | E8: ='Tabelle 1'!C89 -> #DIV/0! | F8: ='Tabelle 1'!C110 -> #DIV/0! | G8: ='Tabelle 1'!C131 -> #DIV/0! | H8: ='Tabelle 1'!C152 -> #DIV/0! | I8: ='Tabelle 1'!C173 -> #DIV/0! | J8: ='Tabelle 1'!C194 -> #DIV/0! | K8: ='Tabelle 1'!C215 -> #DIV/0! | L8: ='Tabelle 1'!C236 -> #DIV/0! | M8: ='Tabelle 1'!C257 -> #DIV/0!
B9: ='Tabelle 1'!C25 -> #DIV/0! | C9: ='Tabelle 1'!C46 -> #DIV/0! | D9: ='Tabelle 1'!C69 -> #DIV/0! | E9: ='Tabelle 1'!C90 -> #DIV/0! | F9: ='Tabelle 1'!C111 -> #DIV/0! | G9: ='Tabelle 1'!C132 -> #DIV/0! | H9: ='Tabelle 1'!C153 -> #DIV/0! | I9: ='Tabelle 1'!C174 -> #DIV/0! | J9: ='Tabelle 1'!C195 -> #DIV/0! | K9: ='Tabelle 1'!C216 -> #DIV/0! | L9: ='Tabelle 1'!C237 -> #DIV/0! | M9: ='Tabelle 1'!C258 -> #DIV/0!
A10: Weight in g | B10: ='Tabelle 1'!D24 -> #DIV/0! | C10: ='Tabelle 1'!D45 -> #DIV/0! | D10: ='Tabelle 1'!D68 -> #DIV/0! | E10: ='Tabelle 1'!D89 -> #DIV/0! | F10: ='Tabelle 1'!D110 -> #DIV/0! | G10: ='Tabelle 1'!D131 -> #DIV/0! | H10: ='Tabelle 1'!D152 -> #DIV/0! | I10: ='Tabelle 1'!D173 -> #DIV/0! | J10: ='Tabelle 1'!D194 -> #DIV/0! | K10: ='Tabelle 1'!D215 -> #DIV/0! | L10: ='Tabelle 1'!D236 -> #DIV/0! | M10: ='Tabelle 1'!D257 -> #DIV/0!
B11: ='Tabelle 1'!D25 -> #DIV/0! | C11: ='Tabelle 1'!D46 -> #DIV/0! | D11: ='Tabelle 1'!D69 -> #DIV/0! | E11: ='Tabelle 1'!D90 -> #DIV/0! | F11: ='Tabelle 1'!D111 -> #DIV/0! | G11: ='Tabelle 1'!D132 -> #DIV/0! | H11: ='Tabelle 1'!D153 -> #DIV/0! | I11: ='Tabelle 1'!D174 -> #DIV/0! | J11: ='Tabelle 1'!D195 -> #DIV/0! | K11: ='Tabelle 1'!D216 -> #DIV/0! | L11: ='Tabelle 1'!D237 -> #DIV/0! | M11: ='Tabelle 1'!D258 -> #DIV/0!
A12: Hypocotyl Discoloration | B12: ='Tabelle 1'!E24 -> #DIV/0! | C12: ='Tabelle 1'!E45 -> #DIV/0! | D12: ='Tabelle 1'!E68 -> #DIV/0! | E12: ='Tabelle 1'!E89 -> #DIV/0! | F12: ='Tabelle 1'!E110 -> #DIV/0! | G12: ='Tabelle 1'!E131 -> #DIV/0! | H12: ='Tabelle 1'!E152 -> #DIV/0! | I12: ='Tabelle 1'!E173 -> #DIV/0! | J12: ='Tabelle 1'!E194 -> #DIV/0! | K12: ='Tabelle 1'!E215 -> #DIV/0! | L12: ='Tabelle 1'!E236 -> #DIV/0! | M12: ='Tabelle 1'!E257 -> #DIV/0!
B13: ='Tabelle 1'!E25 -> #DIV/0! | C13: ='Tabelle 1'!E46 -> #DIV/0! | D13: ='Tabelle 1'!E69 -> #DIV/0! | E13: ='Tabelle 1'!E90 -> #DIV/0! | F13: ='Tabelle 1'!E111 -> #DIV/0! | G13: ='Tabelle 1'!E132 -> #DIV/0! | H13: ='Tabelle 1'!E153 -> #DIV/0! | I13: ='Tabelle 1'!E174 -> #DIV/0! | J13: ='Tabelle 1'!E195 -> #DIV/0! | K13: ='Tabelle 1'!E216 -> #DIV/0! | L13: ='Tabelle 1'!E237 -> #DIV/0! | M13: ='Tabelle 1'!E258 -> #DIV/0!
A14: n | B14: ='Tabelle 1'!G25 -> 15 | C14: ='Tabelle 1'!G46 -> 15 | D14: ='Tabelle 1'!G69 -> 15 | E14: ='Tabelle 1'!G90 -> 15 | F14: ='Tabelle 1'!G111 -> 15 | G14: ='Tabelle 1'!G132 -> 15 | H14: ='Tabelle 1'!G153 -> 15 | I14: ='Tabelle 1'!G174 -> 15 | J14: ='Tabelle 1'!G195 -> 15 | K14: ='Tabelle 1'!G216 -> 15 | L14: ='Tabelle 1'!G237 -> 15 | M14: ='Tabelle 1'!G258 -> 15
I16: T-Test
I18: Plant size
I25: Length of 2nd true leaf in cm
I38: Weight in g

Sheet Degree of Symptoms
A1: ='Tabelle 1'!A1 -> V. dahliae - plant experiment with | I1: ='Tabelle 1'!F1 -> Date
A2: ='Tabelle 1'!A2 -> spore conc. 1x10^7 Sp/ml, infection 40 min root dipping while shaking (35 rpm)
A3: ='Tabelle 1'!A3 -> Infection on (infected 10 day-old seedlings)
A4: ='Tabelle 1'!A4 -> date of measurement:
A8: Height | B8: Symptoms | C8: % | E8: Use Mock mean values as 100% | H8: Degree
B9: dead | C9: 0 | F9: =C9 -> 0 | G9: 0 | H9: 5 | J9: 0 | K9: 5 | L9: das ist die Matrix, mit der verglichen wird. Die Reihenfolge der Größe muss aufsteigend sein
B10: very strong | C10: 0.1 | E10: 39 | F10: =0.001*G13 -> #DIV/0! | G10: =0.39*G13 -> #DIV/0! | H10: 4 | J10: =F10 -> #DIV/0! | K10: 4 | L10: Das Ergebnis habe ich in Tabelle1 bei stem assay reingeschrieben.
B11: strong | C11: 40 | D11: - | E11: 59 | F11: =0.4*G13 -> #DIV/0! | G11: =0.59*G13 -> #DIV/0! | H11: 3 | J11: =F11 -> #DIV/0! | K11: 3
B12: weak | C12: 60 | D12: - | E12: 79 | F12: =0.6*G13 -> #DIV/0! | G12: =0.79*G13 -> #DIV/0! | H12: 2 | J12: =F12 -> #DIV/0! | K12: 2
B13: healthy | C13: 80 | D13: - | E13: 100 | F13: =0.8*G13 -> #DIV/0! | G13: ='Tabelle 1'!B24 -> #DIV/0! | H13: 1 | J13: =F13 -> #DIV/0! | K13: 1
A17: Leaf | B17: Symptoms | C17: % | E17: Use Mock mean values as 100% | H17: Degree
B18: dead | C18: 0 | F18: =C18 -> 0 | H18: 5 | J18: =F18 -> 0 | K18: =H18 -> 5
B19: very strong | C19: 0.1 | E19: 39 | F19: =0.001*G22 -> #DIV/0! | G19: =0.39*G22 -> #DIV/0! | H19: 4 | J19: =F19 -> #DIV/0! | K19: =H19 -> 4
B20: strong | C20: 40 | D20: - | E20: 59 | F20: =0.4*G22 -> #DIV/0! | G20: =0.59*G22 -> #DIV/0! | H20: 3 | J20: =F20 -> #DIV/0! | K20: =H20 -> 3
B21: weak | C21: 60 | D21: - | E21: 79 | F21: =0.6*G22 -> #DIV/0! | G21: =0.79*G22 -> #DIV/0! | H21: 2 | J21: =F21 -> #DIV/0! | K21: =H21 -> 2
B22: healthy | C22: 80 | D22: - | E22: 100 | F22: =0.8*G22 -> #DIV/0! | G22: ='Tabelle 1'!C24 -> #DIV/0! | H22: 1 | J22: =F22 -> #DIV/0! | K22: =H22 -> 1
A25: Weight | B25: Symptoms | C25: % | E25: Use Mock mean values as 100% | H25: Degree
B26: dead | C26: 0 | F26: =C26 -> 0 | H26: 5 | J26: =F26 -> 0 | K26: =H26 -> 5
B27: very strong | C27: 0.1 | E27: 39 | F27: =0.01*$G$30 -> #DIV/0! | G27: =0.39*$G$30 -> #DIV/0! | H27: 4 | J27: =F27 -> #DIV/0! | K27: =H27 -> 4
B28: strong | C28: 40 | D28: - | E28: 59 | F28: =0.4*$G$30 -> #DIV/0! | G28: =0.59*$G$30 -> #DIV/0! | H28: 3 | J28: =F28 -> #DIV/0! | K28: =H28 -> 3
B29: weak | C29: 60 | D29: - | E29: 79 | F29: =0.6*$G$30 -> #DIV/0! | G29: =0.79*$G$30 -> #DIV/0! | H29: 2 | J29: =F29 -> #DIV/0! | K29: =H29 -> 2
B30: healthy | C30: 80 | D30: - | E30: 100 | F30: =0.8*$G$30 -> #DIV/0! | G30: ='Tabelle 1'!D24 -> #DIV/0! | H30: 1 | J30: =F30 -> #DIV/0! | K30: =H30 -> 1

Sheet Tabelle1 (2)
A1: ='Tabelle 1'!A7 -> Mock | B1: Höhe | C1: Blattgröße | D1: Gewicht | E1: zusammen | H1: Anzahl | M1: MOCK | N1: WT | O1: oeLLM1 | R1: Mock | S1: WT | T1: oeLLM1 | W1: Mock | X1: WT | Y1: oeLLM1
A2: 1 | B2: =VLOOKUP('Tabelle 1'!B9,'Degree of Symptoms'!$J$9:$K$13,2) -> 5 | C2: =VLOOKUP('Tabelle 1'!C9,'Degree of Symptoms'!$J$13:$K$22,2) -> 5 | D2: =VLOOKUP('Tabelle 1'!D9,'Degree of Symptoms'!$J$26:$K$30,2) -> 5 | E2: =AVERAGE(B2:D2) -> 5 | G2: 1-1,99 | H2: =COUNTIFS($E$2:$E$16,"<1,99",$E$2:$E$16,">=1") -> 0 | J2: 1-1,99 | L2: healthy | M2: =SUM(R2,R9,R17) -> 87 | N2: =SUM(S2,S9,S17) -> 14 | O2: =SUM(T2,T9,T17) -> 29 | R2: 29 | S2: 4 | T2: 1 | W2: 1 | X2: 1 | Y2: 1
A3: 2 | B3: =VLOOKUP('Tabelle 1'!B10,'Degree of Symptoms'!$J$9:$K$13,2) -> 5 | C3: =VLOOKUP('Tabelle 1'!C10,'Degree of Symptoms'!$J$13:$K$22,2) -> 5 | D3: =VLOOKUP('Tabelle 1'!D10,'Degree of Symptoms'!$J$26:$K$30,2) -> 5 | E3: =AVERAGE(B3:D3) -> 5 | G3: 2-2,99 | H3: =COUNTIFS($E$2:$E$16,"<2,99",$E$2:$E$16,">=2") -> 0 | J3: 2-2,99 | L3: weak symptoms | M3: 3 | N3: =SUM(S3,S10,S18) -> 36 | O3: =SUM(T3,T10,T18) -> 49 | R3: 1 | S3: 15 | T3: 15 | W3: 1 | X3: 1 | Y3: 1
A4: 3 | B4: =VLOOKUP('Tabelle 1'!B11,'Degree of Symptoms'!$J$9:$K$13,2) -> 5 | C4: =VLOOKUP('Tabelle 1'!C11,'Degree of Symptoms'!$J$13:$K$22,2) -> 5 | D4: =VLOOKUP('Tabelle 1'!D11,'Degree of Symptoms'!$J$26:$K$30,2) -> 5 | E4: =AVERAGE(B4:D4) -> 5 | G4: 3-3,99 | H4: =COUNTIFS($E$2:$E$16,"<3,99",$E$2:$E$16,">=3") -> 0 | J4: 3-3,99 | L4: strong symptoms | M4: =H4 -> 0 | N4: =SUM(S4,S11,S19) -> 30 | O4: =SUM(T4,T11,T19) -> 34 | S4: 8 | T4: 13 | W4: 1 | X4: 1 | Y4: 1
A5: 4 | B5: =VLOOKUP('Tabelle 1'!B12,'Degree of Symptoms'!$J$9:$K$13,2) -> 5 | C5: =VLOOKUP('Tabelle 1'!C12,'Degree of Symptoms'!$J$13:$K$22,2) -> 5 | D5: =VLOOKUP('Tabelle 1'!D12,'Degree of Symptoms'!$J$26:$K$30,2) -> 5 | E5: =AVERAGE(B5:D5) -> 5 | G5: 4-4,99 | H5: =COUNTIFS($E$2:$E$16,"<4,99",$E$2:$E$16,">=4") -> 0 | J5: 4-4,99 | L5: very strong symptoms | M5: =H5 -> 0 | N5: =SUM(S5,S12,S20) -> 10 | O5: =SUM(T5,T20) -> 8 | S5: 3 | T5: 1 | W5: 1 | X5: 1 | Y5: 1
A6: 5 | B6: =VLOOKUP('Tabelle 1'!B13,'Degree of Symptoms'!$J$9:$K$13,2) -> 5 | C6: =VLOOKUP('Tabelle 1'!C13,'Degree of Symptoms'!$J$13:$K$22,2) -> 5 | D6: =VLOOKUP('Tabelle 1'!D13,'Degree of Symptoms'!$J$26:$K$30,2) -> 5 | E6: =AVERAGE(B6:D6) -> 5 | G6: 5 | H6: =COUNTIF($E$2:$E$16,">=5") -> 15 | J6: 5 | L6: dead | M6: 0 | N6: 0 | O6: 0 | W6: 1 | X6: 1 | Y6: 1
A7: 6 | B7: =VLOOKUP('Tabelle 1'!B14,'Degree of Symptoms'!$J$9:$K$13,2) -> 5 | C7: =VLOOKUP('Tabelle 1'!C14,'Degree of Symptoms'!$J$13:$K$22,2) -> 5 | D7: =VLOOKUP('Tabelle 1'!D14,'Degree of Symptoms'!$J$26:$K$30,2) -> 5 | E7: =AVERAGE(B7:D7) -> 5 | H7: =SUM(H2:H6) -> 15 | W7: 1 | X7: 1 | Y7: 1
A8: 7 | B8: =VLOOKUP('Tabelle 1'!B15,'Degree of Symptoms'!$J$9:$K$13,2) -> 5 | C8: =VLOOKUP('Tabelle 1'!C15,'Degree of Symptoms'!$J$13:$K$22,2) -> 5 | D8: =VLOOKUP('Tabelle 1'!D15,'Degree of Symptoms'!$J$26:$K$30,2) -> 5 | E8: =AVERAGE(B8:D8) -> 5 | L8: n | M8: =SUM(M2:M7) -> 90 | N8: =SUM(N2:N7) -> 90 | O8: =SUM(O2:O7) -> 120 | R8: Mock | S8: WT | T8: oeLLM1 | W8: 1 | X8: 1 | Y8: 1
A9: 8 | B9: =VLOOKUP('Tabelle 1'!B16,'Degree of Symptoms'!$J$9:$K$13,2) -> 5 | C9: =VLOOKUP('Tabelle 1'!C16,'Degree of Symptoms'!$J$13:$K$22,2) -> 5 | D9: =VLOOKUP('Tabelle 1'!D16,'Degree of Symptoms'!$J$26:$K$30,2) -> 5 | E9: =AVERAGE(B9:D9) -> 5 | R9: 28 | S9: 7 | T9: 18 | W9: 1 | X9: 1 | Y9: 1
A10: 9 | B10: =VLOOKUP('Tabelle 1'!B17,'Degree of Symptoms'!$J$9:$K$13,2) -> 5 | C10: =VLOOKUP('Tabelle 1'!C17,'Degree of Symptoms'!$J$13:$K$22,2) -> 5 | D10: =VLOOKUP('Tabelle 1'!D17,'Degree of Symptoms'!$J$26:$K$30,2) -> 5 | E10: =AVERAGE(B10:D10) -> 5 | R10: 2 | S10: 18 | T10: 9 | W10: 1 | X10: 1 | Y10: 1
A11: 10 | B11: =VLOOKUP('Tabelle 1'!B18,'Degree of Symptoms'!$J$9:$K$13,2) -> 5 | C11: =VLOOKUP('Tabelle 1'!C18,'Degree of Symptoms'!$J$13:$K$22,2) -> 5 | D11: =VLOOKUP('Tabelle 1'!D18,'Degree of Symptoms'!$J$26:$K$30,2) -> 5 | E11: =AVERAGE(B11:D11) -> 5 | R11: 0 | S11: 4 | T11: 3 | W11: 1 | X11: 1 | Y11: 1
A12: 11 | B12: =VLOOKUP('Tabelle 1'!B19,'Degree of Symptoms'!$J$9:$K$13,2) -> 5 | C12: =VLOOKUP('Tabelle 1'!C19,'Degree of Symptoms'!$J$13:$K$22,2) -> 5 | D12: =VLOOKUP('Tabelle 1'!D19,'Degree of Symptoms'!$J$26:$K$30,2) -> 5 | E12: =AVERAGE(B12:D12) -> 5 | R12: 0 | S12: 1 | T12: 0 | W12: 1 | X12: 1 | Y12: 1
A13: 12 | B13: =VLOOKUP('Tabelle 1'!B20,'Degree of Symptoms'!$J$9:$K$13,2) -> 5 | C13: =VLOOKUP('Tabelle 1'!C20,'Degree of Symptoms'!$J$13:$K$22,2) -> 5 | D13: =VLOOKUP('Tabelle 1'!D20,'Degree of Symptoms'!$J$26:$K$30,2) -> 5 | E13: =AVERAGE(B13:D13) -> 5 | R13: 0 | S13: 0 | T13: 0 | W13: 1 | X13: 1 | Y13: 1
A14: 13 | B14: =VLOOKUP('Tabelle 1'!B21,'Degree of Symptoms'!$J$9:$K$13,2) -> 5 | C14: =VLOOKUP('Tabelle 1'!C21,'Degree of Symptoms'!$J$13:$K$22,2) -> 5 | D14: =VLOOKUP('Tabelle 1'!D21,'Degree of Symptoms'!$J$26:$K$30,2) -> 5 | E14: =AVERAGE(B14:D14) -> 5 | W14: 1 | X14: 1 | Y14: 1
A15: 14 | B15: =VLOOKUP('Tabelle 1'!B22,'Degree of Symptoms'!$J$9:$K$13,2) -> 5 | C15: =VLOOKUP('Tabelle 1'!C22,'Degree of Symptoms'!$J$13:$K$22,2) -> 5 | D15: =VLOOKUP('Tabelle 1'!D22,'Degree of Symptoms'!$J$26:$K$30,2) -> 5 | E15: =AVERAGE(B15:D15) -> 5 | W15: 1 | X15: 1 | Y15: 1
A16: 15 | B16: =VLOOKUP('Tabelle 1'!B23,'Degree of Symptoms'!$J$9:$K$13,2) -> 5 | C16: =VLOOKUP('Tabelle 1'!C23,'Degree of Symptoms'!$J$13:$K$22,2) -> 5 | D16: =VLOOKUP('Tabelle 1'!D23,'Degree of Symptoms'!$J$26:$K$30,2) -> 5 | E16: =AVERAGE(B16:D16) -> 5 | R16: Mock | S16: WT | T16: oeLLM1 | W16: 1 | X16: 2 | Y16: 1
F17: n | R17: 30 | S17: 3 | T17: 10 | W17: 1 | X17: 2 | Y17: 1
A18: Mittelwert | B18: =AVERAGE(B2:B16) -> 5 | C18: =AVERAGE(C2:C16) -> 5 | D18: =AVERAGE(D2:D16) -> 5 | E18: =AVERAGE(E2:E16) -> 5 | F18: ='Tabelle 1'!G25 -> 15 | R18: 0 | S18: 3 | T18: 25 | W18: 1 | X18: 2 | Y18: 1
A19: Fehler | B19: =STDEV(B2:B16) -> 0 | C19: =STDEV(C2:C16) -> 0 | D19: =STDEV(D2:D16) -> 0 | E19: =STDEV(E2:E16) -> 0 | R19: 0 | S19: 18 | T19: 18 | W19: 1 | X19: 2 | Y19: 1
R20: 0 | S20: 6 | T20: 7 | W20: 1 | X20: 2 | Y20: 1
R21: 0 | S21: 0 | T21: 0 | W21: 1 | X21: 2 | Y21: 1
A22: ='Tabelle 1'!A28 -> WT JR2 | B22: Höhe | C22: Blattgröße | D22: Gewicht | E22: zusammen | H22: Anzahl | W22: 1 | X22: 2 | Y22: 1
A23: 1 | B23: =VLOOKUP('Tabelle 1'!B30,'Degree of Symptoms'!$J$9:$K$13,2) -> 5 | C23: =VLOOKUP('Tabelle 1'!C30,'Degree of Symptoms'!$J$13:$K$22,2) -> 5 | D23: =VLOOKUP('Tabelle 1'!D30,'Degree of Symptoms'!$J$26:$K$30,2) -> 5 | E23: =AVERAGE(B23:D23) -> 5 | G23: 1-1,99 | H23: =COUNTIFS($E$23:$E$37,"<1,99",$E$23:$E$37,">=1") -> 0 | W23: 1 | X23: 2 | Y23: 1
A24: 2 | B24: =VLOOKUP('Tabelle 1'!B31,'Degree of Symptoms'!$J$9:$K$13,2) -> 5 | C24: =VLOOKUP('Tabelle 1'!C31,'Degree of Symptoms'!$J$13:$K$22,2) -> 5 | D24: =VLOOKUP('Tabelle 1'!D31,'Degree of Symptoms'!$J$26:$K$30,2) -> 5 | E24: =AVERAGE(B24:D24) -> 5 | G24: 2-2,99 | H24: =COUNTIFS($E$23:$E$37,"<2,99",$E$23:$E$37,">=2") -> 0 | W24: 1 | X24: 2 | Y24: 1
A25: 3 | B25: =VLOOKUP('Tabelle 1'!B32,'Degree of Symptoms'!$J$9:$K$13,2) -> 5 | C25: =VLOOKUP('Tabelle 1'!C32,'Degree of Symptoms'!$J$13:$K$22,2) -> 5 | D25: =VLOOKUP('Tabelle 1'!D32,'Degree of Symptoms'!$J$26:$K$30,2) -> 5 | E25: =AVERAGE(B25:D25) -> 5 | G25: 3-3,99 | H25: =COUNTIFS($E$23:$E$37,"<3,99",$E$23:$E$37,">=3") -> 0 | W25: 1 | X25: 2 | Y25: 1
A26: 4 | B26: =VLOOKUP('Tabelle 1'!B33,'Degree of Symptoms'!$J$9:$K$13,2) -> 5 | C26: =VLOOKUP('Tabelle 1'!C33,'Degree of Symptoms'!$J$13:$K$22,2) -> 5 | D26: =VLOOKUP('Tabelle 1'!D33,'Degree of Symptoms'!$J$26:$K$30,2) -> 5 | E26: =AVERAGE(B26:D26) -> 5 | G26: 4-4,99 | H26: =COUNTIFS($E$23:$E$37,"<4,99",$E$23:$E$37,">=4") -> 0 | W26: 1 | X26: 2 | Y26: 1
A27: 5 | B27: =VLOOKUP('Tabelle 1'!B34,'Degree of Symptoms'!$J$9:$K$13,2) -> 5 | C27: =VLOOKUP('Tabelle 1'!C34,'Degree of Symptoms'!$J$13:$K$22,2) -> 5 | D27: =VLOOKUP('Tabelle 1'!D34,'Degree of Symptoms'!$J$26:$K$30,2) -> 5 | E27: =AVERAGE(B27:D27) -> 5 | G27: 5 | H27: =COUNTIF($E$23:$E$37,">=5") -> 15 | W27: 1 | X27: 2 | Y27: 1
A28: 6 | B28: =VLOOKUP('Tabelle 1'!B35,'Degree of Symptoms'!$J$9:$K$13,2) -> 5 | C28: =VLOOKUP('Tabelle 1'!C35,'Degree of Symptoms'!$J$13:$K$22,2) -> 5 | D28: =VLOOKUP('Tabelle 1'!D35,'Degree of Symptoms'!$J$26:$K$30,2) -> 5 | E28: =AVERAGE(B28:D28) -> 5 | H28: =SUM(H23:H27) -> 15 | W28: 1 | X28: 2 | Y28: 1
A29: 7 | B29: =VLOOKUP('Tabelle 1'!B36,'Degree of Symptoms'!$J$9:$K$13,2) -> 5 | C29: =VLOOKUP('Tabelle 1'!C36,'Degree of Symptoms'!$J$13:$K$22,2) -> 5 | D29: =VLOOKUP('Tabelle 1'!D36,'Degree of Symptoms'!$J$26:$K$30,2) -> 5 | E29: =AVERAGE(B29:D29) -> 5 | W29: 1 | X29: 2 | Y29: 1
A30: 8 | B30: =VLOOKUP('Tabelle 1'!B37,'Degree of Symptoms'!$J$9:$K$13,2) -> 5 | C30: =VLOOKUP('Tabelle 1'!C37,'Degree of Symptoms'!$J$13:$K$22,2) -> 5 | D30: =VLOOKUP('Tabelle 1'!D37,'Degree of Symptoms'!$J$26:$K$30,2) -> 5 | E30: =AVERAGE(B30:D30) -> 5 | F30: nicht verfärbt | W30: 1 | X30: 2 | Y30: 1
A31: 9 | B31: =VLOOKUP('Tabelle 1'!B38,'Degree of Symptoms'!$J$9:$K$13,2) -> 5 | C31: =VLOOKUP('Tabelle 1'!C38,'Degree of Symptoms'!$J$13:$K$22,2) -> 5 | D31: =VLOOKUP('Tabelle 1'!D38,'Degree of Symptoms'!$J$26:$K$30,2) -> 5 | E31: =AVERAGE(B31:D31) -> 5 | W31: 1 | X31: 2 | Y31: 2
A32: 10 | B32: =VLOOKUP('Tabelle 1'!B39,'Degree of Symptoms'!$J$9:$K$13,2) -> 5 | C32: =VLOOKUP('Tabelle 1'!C39,'Degree of Symptoms'!$J$13:$K$22,2) -> 5 | D32: =VLOOKUP('Tabelle 1'!D39,'Degree of Symptoms'!$J$26:$K$30,2) -> 5 | E32: =AVERAGE(B32:D32) -> 5 | W32: 1 | X32: 2 | Y32: 2
A33: 11 | B33: =VLOOKUP('Tabelle 1'!B40,'Degree of Symptoms'!$J$9:$K$13,2) -> 5 | C33: =VLOOKUP('Tabelle 1'!C40,'Degree of Symptoms'!$J$13:$K$22,2) -> 5 | D33: =VLOOKUP('Tabelle 1'!D40,'Degree of Symptoms'!$J$26:$K$30,2) -> 5 | E33: =AVERAGE(B33:D33) -> 5 | W33: 1 | X33: 2 | Y33: 2
A34: 12 | B34: =VLOOKUP('Tabelle 1'!B41,'Degree of Symptoms'!$J$9:$K$13,2) -> 5 | C34: =VLOOKUP('Tabelle 1'!C41,'Degree of Symptoms'!$J$13:$K$22,2) -> 5 | D34: =VLOOKUP('Tabelle 1'!D41,'Degree of Symptoms'!$J$26:$K$30,2) -> 5 | E34: =AVERAGE(B34:D34) -> 5 | W34: 1 | X34: 2 | Y34: 2
A35: 13 | B35: =VLOOKUP('Tabelle 1'!B42,'Degree of Symptoms'!$J$9:$K$13,2) -> 5 | C35: =VLOOKUP('Tabelle 1'!C42,'Degree of Symptoms'!$J$13:$K$22,2) -> 5 | D35: =VLOOKUP('Tabelle 1'!D42,'Degree of Symptoms'!$J$26:$K$30,2) -> 5 | E35: =AVERAGE(B35:D35) -> 5 | W35: 1 | X35: 2 | Y35: 2
A36: 14 | B36: =VLOOKUP('Tabelle 1'!B43,'Degree of Symptoms'!$J$9:$K$13,2) -> 5 | C36: =VLOOKUP('Tabelle 1'!C43,'Degree of Symptoms'!$J$13:$K$22,2) -> 5 | D36: =VLOOKUP('Tabelle 1'!D43,'Degree of Symptoms'!$J$26:$K$30,2) -> 5 | E36: =AVERAGE(B36:D36) -> 5 | W36: 1 | X36: 2 | Y36: 2
A37: 15 | B37: =VLOOKUP('Tabelle 1'!B44,'Degree of Symptoms'!$J$9:$K$13,2) -> 5 | C37: =VLOOKUP('Tabelle 1'!C44,'Degree of Symptoms'!$J$13:$K$22,2) -> 5 | D37: =VLOOKUP('Tabelle 1'!D44,'Degree of Symptoms'!$J$26:$K$30,2) -> 5 | E37: =AVERAGE(B37:D37) -> 5 | W37: 1 | X37: 2 | Y37: 2
F38: n | W38: 1 | X38: 2 | Y38: 2
A39: Mittelwert | B39: =AVERAGE(B23:B37) -> 5 | C39: =AVERAGE(C23:C37) -> 5 | D39: =AVERAGE(D23:D37) -> 5 | E39: =AVERAGE(E23:E37) -> 5 | F39: ='Tabelle 1'!G46 -> 15 | W39: 1 | X39: 2 | Y39: 2
A40: Fehler | B40: =STDEV(B23:B37) -> 0 | C40: =STDEV(C23:C37) -> 0 | D40: =STDEV(D23:D37) -> 0 | E40: =STDEV(E23:E37) -> 0 | W40: 1 | X40: 2 | Y40: 2
...

Sheet Diagramm4
